package meowmel.pollution.common.metatileentity.multiblock.bot;

import gregtech.api.metatileentity.MetaTileEntity;
import gregtech.api.metatileentity.interfaces.IGregTechTileEntity;
import gregtech.api.metatileentity.multiblock.IMultiblockPart;
import gregtech.api.pattern.casing.DeclarativePatternBuilder;
import gregtech.api.pattern.element.StructureDefinition;
import gregtech.client.renderer.ICubeRenderer;
import gregtech.client.renderer.texture.Textures;
import gregtech.common.blocks.MetaBlocks;
import gregtech.core.sound.GTSoundEvents;
import meowmel.pollution.api.metatileentity.ManaMultiblockController;
import meowmel.pollution.api.unification.PollutionMaterials;
import meowmel.pollution.client.textures.POTextures;
import meowmel.pollution.common.block.PollutionMetaBlocks;
import meowmel.pollution.common.block.metablocks.POMBeamCore;
import net.minecraft.block.state.IBlockState;
import net.minecraft.util.ResourceLocation;
import net.minecraft.util.SoundEvent;
import net.minecraftforge.fml.relauncher.Side;
import net.minecraftforge.fml.relauncher.SideOnly;
import vazkii.botania.api.state.BotaniaStateProps;
import vazkii.botania.api.state.enums.LivingRockVariant;
import vazkii.botania.api.state.enums.LivingWoodVariant;
import vazkii.botania.api.state.enums.PylonVariant;
import vazkii.botania.common.block.ModBlocks;

import static meowmel.pollution.api.recipes.PORecipeMaps.MANA_PETAL_RECIPES;

public class MetaTileEntityManaPetalApothecary extends ManaMultiblockController {

	public MetaTileEntityManaPetalApothecary(ResourceLocation metaTileEntityId) {
		super(metaTileEntityId, MANA_PETAL_RECIPES);
	}

	public MetaTileEntity createMetaTileEntity(IGregTechTileEntity tileEntity) {
		return new MetaTileEntityManaPetalApothecary(this.metaTileEntityId);
	}

	@Override
	protected StructureDefinition<?> createStructureDefinition() {
		DeclarativePatternBuilder builder = DeclarativePatternBuilder.start()
				.aisle("       A       ", "               ", "               ", "               ", "               ", "               ", "               ", "               ", "               ", "               ", "               ", "               ")
				.aisle("      AAA      ", "       A       ", "       B       ", "       C       ", "               ", "               ", "               ", "               ", "               ", "               ", "               ", "               ")
				.aisle("       A       ", "               ", "               ", "               ", "               ", "               ", "               ", "               ", "               ", "               ", "               ", "               ")
				.aisle("       D       ", "               ", "               ", "               ", "               ", "               ", "               ", "               ", "               ", "   AEEEEEEEA   ", "   AFFFFFFFA   ", "   GADDDDDAG   ")
				.aisle("     AAAAA     ", "               ", "               ", "               ", "               ", "               ", "               ", "               ", "    AEEEEEA    ", "   E       E   ", "   F       F   ", "   AAEEEEEAA   ")
				.aisle("    AEEEEEA    ", "     EEEEE     ", "               ", "               ", "               ", "               ", "               ", "     AAAAA     ", "    E     E    ", "   E       E   ", "   F       F   ", "   DE     ED   ")
				.aisle(" A  AEEEEEA  A ", "     EEEEE     ", "      ADA      ", "      ADA      ", "      ADA      ", "      ADA      ", "      ADA      ", "     AEEEA     ", "    E     E    ", "   E       E   ", "   F       F   ", "   DE     ED   ")
				.aisle("AAADAEEEEEADAAA", " A   EEEEE   A ", " B    D D    A ", " C    D D    C ", "      D D      ", "      D D      ", "      D D      ", "     AEEEA     ", "    E     E    ", "   E       E   ", "   F       F   ", "   DE     ED   ")
				.aisle(" A  AEEEEEA  A ", "     EEEEE     ", "      ADA      ", "      ADA      ", "      ADA      ", "      ADA      ", "      ADA      ", "     AEEEA     ", "    E     E    ", "   E       E   ", "   F       F   ", "   DE     ED   ")
				.aisle("    AEEEEEA    ", "     EESEE     ", "               ", "               ", "               ", "               ", "               ", "     AAAAA     ", "    E     E    ", "   E       E   ", "   F       F   ", "   DE     ED   ")
				.aisle("     AAAAA     ", "               ", "               ", "               ", "               ", "               ", "               ", "               ", "    AEEEEEA    ", "   E       E   ", "   F       F   ", "   AAEEEEEAA   ")
				.aisle("       D       ", "               ", "               ", "               ", "               ", "               ", "               ", "               ", "               ", "   AEEEEEEEA   ", "   AFFFFFFFA   ", "   GADDDDDAG   ")
				.aisle("       A       ", "               ", "               ", "               ", "               ", "               ", "               ", "               ", "               ", "               ", "               ", "               ")
				.aisle("      AAA      ", "       A       ", "       B       ", "       C       ", "               ", "               ", "               ", "               ", "               ", "               ", "               ", "               ")
				.aisle("       A       ", "               ", "               ", "               ", "               ", "               ", "               ", "               ", "               ", "               ", "               ", "               ")
				.self('S', MetaTileEntityManaPetalApothecary.class)
				.block('A', getCasingState()).block('B', getCasingState2()).block('C', getCasingState3())
				.block('D', getCasingState4()).block('E', getCasingState5()).block('F', getCasingState6())
				.block('G', getCasingState7()).any(' ');
		return configureManaRecipeCasing(builder, 'E', getCasingState5(), MANA_PETAL_RECIPES, 117)
				.buildStructureDefinition();
	}
	@SideOnly(Side.CLIENT)
	public ICubeRenderer getBaseTexture(IMultiblockPart sourcePart) {
		return POTextures.Livingrock_0;
	}

	protected IBlockState getCasingState() {
		return ModBlocks.livingrock.getDefaultState().withProperty(BotaniaStateProps.LIVINGROCK_VARIANT, LivingRockVariant.CHISELED_BRICK);
	}
	protected IBlockState getCasingState2() {
		return PollutionMetaBlocks.BEAM_CORE.getState(POMBeamCore.MagicBlockType.BEAM_CORE_4);
	}
	protected IBlockState getCasingState3() {
		return ModBlocks.floatingFlower.getDefaultState();
	}
	protected IBlockState getCasingState4() {
		return MetaBlocks.FRAMES.get(PollutionMaterials.Mansussteel).getBlock(PollutionMaterials.Mansussteel);
	}
	protected IBlockState getCasingState5() {
		return ModBlocks.livingrock.getDefaultState().withProperty(BotaniaStateProps.LIVINGROCK_VARIANT, LivingRockVariant.BRICK);
	}
	protected IBlockState getCasingState6() {
		return ModBlocks.livingwood.getDefaultState().withProperty(BotaniaStateProps.LIVINGWOOD_VARIANT, LivingWoodVariant.PLANKS);
	}
	protected IBlockState getCasingState7() {
		return ModBlocks.pylon.getDefaultState().withProperty(BotaniaStateProps.PYLON_VARIANT, PylonVariant.MANA);
	}

	public SoundEvent getBreakdownSound() {
		return GTSoundEvents.BREAKDOWN_ELECTRICAL;
	}

	@SideOnly(Side.CLIENT)
	protected  ICubeRenderer getFrontOverlay() {
		return Textures.HPCA_OVERLAY;
	}
}

